Workbook

Sheet Predicciones_Hugo
A1: Partido | B1: Grupo | C1: Local | D1: Visitante | E1: G_Local | F1: G_Visitante | G1: Resultado | H1: Diferencia | J1: Grupo | K1: Posición | L1: Equipo | M1: Puntos | N1: Diferencia | O1: GF | P1: GC | Q1: Victorias | R1: Empates | S1: Derrotas | T1: Victorias_L | U1: Victorias_V | V1: Empates_L | W1: Empates_V | X1: Derrotas_L | Y1: Derrotas_V | Z1: GF_L | AA1: GF_V | AB1: GC_L | AC1: GC_V
A2: 1 | B2: A | C2: México | D2: Sudáfrica | E2: 2 | F2: 1 | G2: =IF(E2>F2,"Local",IF(E2=F2,"Empate","Visitante")) | H2: =E2-F2 | J2: A | K2: 1 | L2: México | M2: =(Q2*3)+R2 | N2: =O2-P2 | O2: =Z2+AA2 | P2: =AB2+AC2 | Q2: =T2+U2 | R2: =V2+W2 | S2: =X2+Y2 | T2: =COUNTIFS(C:C,L2,G:G,"Local") | U2: =COUNTIFS(D:D,L2,G:G,"Visitante") | V2: =COUNTIFS(C:C,L2,G:G,"Empate") | W2: =COUNTIFS(D:D,L2,G:G,"Empate") | X2: =COUNTIFS(C:C,L2,G:G,"Visitante") | Y2: =COUNTIFS(D:D,L2,G:G,"Local") | Z2: =SUMIF(C:C,L2,E:E) | AA2: =SUMIF(D:D,L2,F:F) | AB2: =SUMIF(C:C,L2,F:F) | AC2: =SUMIF(D:D,L2,E:E)
A3: 2 | B3: A | C3: Corea del Sur | D3: República Checa | E3: 2 | F3: 1 | G3: =IF(E3>F3,"Local",IF(E3=F3,"Empate","Visitante")) | H3: =E3-F3 | K3: 2 | L3: Sudáfrica | M3: =(Q3*3)+R3 | N3: =O3-P3 | O3: =Z3+AA3 | P3: =AB3+AC3 | Q3: =T3+U3 | R3: =V3+W3 | S3: =X3+Y3 | T3: =COUNTIFS(C:C,L3,G:G,"Local") | U3: =COUNTIFS(D:D,L3,G:G,"Visitante") | V3: =COUNTIFS(C:C,L3,G:G,"Empate") | W3: =COUNTIFS(D:D,L3,G:G,"Empate") | X3: =COUNTIFS(C:C,L3,G:G,"Visitante") | Y3: =COUNTIFS(D:D,L3,G:G,"Local") | Z3: =SUMIF(C:C,L3,E:E) | AA3: =SUMIF(D:D,L3,F:F) | AB3: =SUMIF(C:C,L3,F:F) | AC3: =SUMIF(D:D,L3,E:E)
A4: 3 | B4: A | C4: República Checa | D4: Sudáfrica | E4: 1 | F4: 1 | G4: =IF(E4>F4,"Local",IF(E4=F4,"Empate","Visitante")) | H4: =E4-F4 | K4: 3 | L4: República Checa | M4: =(Q4*3)+R4 | N4: =O4-P4 | O4: =Z4+AA4 | P4: =AB4+AC4 | Q4: =T4+U4 | R4: =V4+W4 | S4: =X4+Y4 | T4: =COUNTIFS(C:C,L4,G:G,"Local") | U4: =COUNTIFS(D:D,L4,G:G,"Visitante") | V4: =COUNTIFS(C:C,L4,G:G,"Empate") | W4: =COUNTIFS(D:D,L4,G:G,"Empate") | X4: =COUNTIFS(C:C,L4,G:G,"Visitante") | Y4: =COUNTIFS(D:D,L4,G:G,"Local") | Z4: =SUMIF(C:C,L4,E:E) | AA4: =SUMIF(D:D,L4,F:F) | AB4: =SUMIF(C:C,L4,F:F) | AC4: =SUMIF(D:D,L4,E:E)
A5: 4 | B5: A | C5: México | D5: Corea del Sur | E5: 1 | F5: 0 | G5: =IF(E5>F5,"Local",IF(E5=F5,"Empate","Visitante")) | H5: =E5-F5 | K5: 4 | L5: Corea del Sur | M5: =(Q5*3)+R5 | N5: =O5-P5 | O5: =Z5+AA5 | P5: =AB5+AC5 | Q5: =T5+U5 | R5: =V5+W5 | S5: =X5+Y5 | T5: =COUNTIFS(C:C,L5,G:G,"Local") | U5: =COUNTIFS(D:D,L5,G:G,"Visitante") | V5: =COUNTIFS(C:C,L5,G:G,"Empate") | W5: =COUNTIFS(D:D,L5,G:G,"Empate") | X5: =COUNTIFS(C:C,L5,G:G,"Visitante") | Y5: =COUNTIFS(D:D,L5,G:G,"Local") | Z5: =SUMIF(C:C,L5,E:E) | AA5: =SUMIF(D:D,L5,F:F) | AB5: =SUMIF(C:C,L5,F:F) | AC5: =SUMIF(D:D,L5,E:E)
A6: 5 | B6: A | C6: República Checa | D6: México | E6: 2 | F6: 1 | G6: =IF(E6>F6,"Local",IF(E6=F6,"Empate","Visitante")) | H6: =E6-F6
A7: 6 | B7: A | C7: Sudáfrica | D7: Corea del Sur | E7: 2 | F7: 0 | G7: =IF(E7>F7,"Local",IF(E7=F7,"Empate","Visitante")) | H7: =E7-F7 | J7: Grupo | K7: Posición | L7: Equipo | M7: Puntos | N7: Diferencia | O7: GF | P7: GC | Q7: Victorias | R7: Empates | S7: Derrotas | T7: Victorias_L | U7: Victorias_V | V7: Empates_L | W7: Empates_V | X7: Derrotas_L | Y7: Derrotas_V | Z7: GF_L | AA7: GF_V | AB7: GC_L | AC7: GC_V
A8: 7 | B8: B | C8: Canadá | D8: Bosnia y Herzegovina | E8: 2 | F8: 0 | G8: =IF(E8>F8,"Local",IF(E8=F8,"Empate","Visitante")) | H8: =E8-F8 | J8: B | K8: 1 | L8: Suiza | M8: =(Q8*3)+R8 | N8: =O8-P8 | O8: =Z8+AA8 | P8: =AB8+AC8 | Q8: =T8+U8 | R8: =V8+W8 | S8: =X8+Y8 | T8: =COUNTIFS(C:C,L8,G:G,"Local") | U8: =COUNTIFS(D:D,L8,G:G,"Visitante") | V8: =COUNTIFS(C:C,L8,G:G,"Empate") | W8: =COUNTIFS(D:D,L8,G:G,"Empate") | X8: =COUNTIFS(C:C,L8,G:G,"Visitante") | Y8: =COUNTIFS(D:D,L8,G:G,"Local") | Z8: =SUMIF(C:C,L8,E:E) | AA8: =SUMIF(D:D,L8,F:F) | AB8: =SUMIF(C:C,L8,F:F) | AC8: =SUMIF(D:D,L8,E:E)
A9: 8 | B9: B | C9: Catar | D9: Suiza | E9: 0 | F9: 3 | G9: =IF(E9>F9,"Local",IF(E9=F9,"Empate","Visitante")) | H9: =E9-F9 | K9: 2 | L9: Canadá | M9: =(Q9*3)+R9 | N9: =O9-P9 | O9: =Z9+AA9 | P9: =AB9+AC9 | Q9: =T9+U9 | R9: =V9+W9 | S9: =X9+Y9 | T9: =COUNTIFS(C:C,L9,G:G,"Local") | U9: =COUNTIFS(D:D,L9,G:G,"Visitante") | V9: =COUNTIFS(C:C,L9,G:G,"Empate") | W9: =COUNTIFS(D:D,L9,G:G,"Empate") | X9: =COUNTIFS(C:C,L9,G:G,"Visitante") | Y9: =COUNTIFS(D:D,L9,G:G,"Local") | Z9: =SUMIF(C:C,L9,E:E) | AA9: =SUMIF(D:D,L9,F:F) | AB9: =SUMIF(C:C,L9,F:F) | AC9: =SUMIF(D:D,L9,E:E)
A10: 9 | B10: B | C10: Suiza | D10: Bosnia y Herzegovina | E10: 2 | F10: 0 | G10: =IF(E10>F10,"Local",IF(E10=F10,"Empate","Visitante")) | H10: =E10-F10 | K10: 3 | L10: Bosnia y Herzegovina | M10: =(Q10*3)+R10 | N10: =O10-P10 | O10: =Z10+AA10 | P10: =AB10+AC10 | Q10: =T10+U10 | R10: =V10+W10 | S10: =X10+Y10 | T10: =COUNTIFS(C:C,L10,G:G,"Local") | U10: =COUNTIFS(D:D,L10,G:G,"Visitante") | V10: =COUNTIFS(C:C,L10,G:G,"Empate") | W10: =COUNTIFS(D:D,L10,G:G,"Empate") | X10: =COUNTIFS(C:C,L10,G:G,"Visitante") | Y10: =COUNTIFS(D:D,L10,G:G,"Local") | Z10: =SUMIF(C:C,L10,E:E) | AA10: =SUMIF(D:D,L10,F:F) | AB10: =SUMIF(C:C,L10,F:F) | AC10: =SUMIF(D:D,L10,E:E)
A11: 10 | B11: B | C11: Canadá | D11: Catar | E11: 3 | F11: 1 | G11: =IF(E11>F11,"Local",IF(E11=F11,"Empate","Visitante")) | H11: =E11-F11 | K11: 4 | L11: Catar | M11: =(Q11*3)+R11 | N11: =O11-P11 | O11: =Z11+AA11 | P11: =AB11+AC11 | Q11: =T11+U11 | R11: =V11+W11 | S11: =X11+Y11 | T11: =COUNTIFS(C:C,L11,G:G,"Local") | U11: =COUNTIFS(D:D,L11,G:G,"Visitante") | V11: =COUNTIFS(C:C,L11,G:G,"Empate") | W11: =COUNTIFS(D:D,L11,G:G,"Empate") | X11: =COUNTIFS(C:C,L11,G:G,"Visitante") | Y11: =COUNTIFS(D:D,L11,G:G,"Local") | Z11: =SUMIF(C:C,L11,E:E) | AA11: =SUMIF(D:D,L11,F:F) | AB11: =SUMIF(C:C,L11,F:F) | AC11: =SUMIF(D:D,L11,E:E)
A12: 11 | B12: B | C12: Suiza | D12: Canadá | E12: 1 | F12: 0 | G12: =IF(E12>F12,"Local",IF(E12=F12,"Empate","Visitante")) | H12: =E12-F12
A13: 12 | B13: B | C13: Bosnia y Herzegovina | D13: Catar | E13: 1 | F13: 0 | G13: =IF(E13>F13,"Local",IF(E13=F13,"Empate","Visitante")) | H13: =E13-F13 | J13: Grupo | K13: Posición | L13: Equipo | M13: Puntos | N13: Diferencia | O13: GF | P13: GC | Q13: Victorias | R13: Empates | S13: Derrotas | T13: Victorias_L | U13: Victorias_V | V13: Empates_L | W13: Empates_V | X13: Derrotas_L | Y13: Derrotas_V | Z13: GF_L | AA13: GF_V | AB13: GC_L | AC13: GC_V
A14: 13 | B14: C | C14: Brasil | D14: Marruecos | E14: 2 | F14: 0 | G14: =IF(E14>F14,"Local",IF(E14=F14,"Empate","Visitante")) | H14: =E14-F14 | J14: C | K14: 1 | L14: Brasil | M14: =(Q14*3)+R14 | N14: =O14-P14 | O14: =Z14+AA14 | P14: =AB14+AC14 | Q14: =T14+U14 | R14: =V14+W14 | S14: =X14+Y14 | T14: =COUNTIFS(C:C,L14,G:G,"Local") | U14: =COUNTIFS(D:D,L14,G:G,"Visitante") | V14: =COUNTIFS(C:C,L14,G:G,"Empate") | W14: =COUNTIFS(D:D,L14,G:G,"Empate") | X14: =COUNTIFS(C:C,L14,G:G,"Visitante") | Y14: =COUNTIFS(D:D,L14,G:G,"Local") | Z14: =SUMIF(C:C,L14,E:E) | AA14: =SUMIF(D:D,L14,F:F) | AB14: =SUMIF(C:C,L14,F:F) | AC14: =SUMIF(D:D,L14,E:E)
A15: 14 | B15: C | C15: Haití | D15: Escocia | E15: 0 | F15: 3 | G15: =IF(E15>F15,"Local",IF(E15=F15,"Empate","Visitante")) | H15: =E15-F15 | K15: 2 | L15: Marruecos | M15: =(Q15*3)+R15 | N15: =O15-P15 | O15: =Z15+AA15 | P15: =AB15+AC15 | Q15: =T15+U15 | R15: =V15+W15 | S15: =X15+Y15 | T15: =COUNTIFS(C:C,L15,G:G,"Local") | U15: =COUNTIFS(D:D,L15,G:G,"Visitante") | V15: =COUNTIFS(C:C,L15,G:G,"Empate") | W15: =COUNTIFS(D:D,L15,G:G,"Empate") | X15: =COUNTIFS(C:C,L15,G:G,"Visitante") | Y15: =COUNTIFS(D:D,L15,G:G,"Local") | Z15: =SUMIF(C:C,L15,E:E) | AA15: =SUMIF(D:D,L15,F:F) | AB15: =SUMIF(C:C,L15,F:F) | AC15: =SUMIF(D:D,L15,E:E)
A16: 15 | B16: C | C16: Escocia | D16: Marruecos | E16: 1 | F16: 4 | G16: =IF(E16>F16,"Local",IF(E16=F16,"Empate","Visitante")) | H16: =E16-F16 | K16: 3 | L16: Escocia | M16: =(Q16*3)+R16 | N16: =O16-P16 | O16: =Z16+AA16 | P16: =AB16+AC16 | Q16: =T16+U16 | R16: =V16+W16 | S16: =X16+Y16 | T16: =COUNTIFS(C:C,L16,G:G,"Local") | U16: =COUNTIFS(D:D,L16,G:G,"Visitante") | V16: =COUNTIFS(C:C,L16,G:G,"Empate") | W16: =COUNTIFS(D:D,L16,G:G,"Empate") | X16: =COUNTIFS(C:C,L16,G:G,"Visitante") | Y16: =COUNTIFS(D:D,L16,G:G,"Local") | Z16: =SUMIF(C:C,L16,E:E) | AA16: =SUMIF(D:D,L16,F:F) | AB16: =SUMIF(C:C,L16,F:F) | AC16: =SUMIF(D:D,L16,E:E)
A17: 16 | B17: C | C17: Brasil | D17: Haití | E17: 5 | F17: 0 | G17: =IF(E17>F17,"Local",IF(E17=F17,"Empate","Visitante")) | H17: =E17-F17 | K17: 4 | L17: Haití | M17: =(Q17*3)+R17 | N17: =O17-P17 | O17: =Z17+AA17 | P17: =AB17+AC17 | Q17: =T17+U17 | R17: =V17+W17 | S17: =X17+Y17 | T17: =COUNTIFS(C:C,L17,G:G,"Local") | U17: =COUNTIFS(D:D,L17,G:G,"Visitante") | V17: =COUNTIFS(C:C,L17,G:G,"Empate") | W17: =COUNTIFS(D:D,L17,G:G,"Empate") | X17: =COUNTIFS(C:C,L17,G:G,"Visitante") | Y17: =COUNTIFS(D:D,L17,G:G,"Local") | Z17: =SUMIF(C:C,L17,E:E) | AA17: =SUMIF(D:D,L17,F:F) | AB17: =SUMIF(C:C,L17,F:F) | AC17: =SUMIF(D:D,L17,E:E)
A18: 17 | B18: C | C18: Escocia | D18: Brasil | E18: 2 | F18: 3 | G18: =IF(E18>F18,"Local",IF(E18=F18,"Empate","Visitante")) | H18: =E18-F18
A19: 18 | B19: C | C19: Marruecos | D19: Haití | E19: 3 | F19: 0 | G19: =IF(E19>F19,"Local",IF(E19=F19,"Empate","Visitante")) | H19: =E19-F19 | J19: Grupo | K19: Posición | L19: Equipo | M19: Puntos | N19: Diferencia | O19: GF | P19: GC | Q19: Victorias | R19: Empates | S19: Derrotas | T19: Victorias_L | U19: Victorias_V | V19: Empates_L | W19: Empates_V | X19: Derrotas_L | Y19: Derrotas_V | Z19: GF_L | AA19: GF_V | AB19: GC_L | AC19: GC_V
A20: 19 | B20: D | C20: Estados Unidos | D20: Paraguay | E20: 2 | F20: 0 | G20: =IF(E20>F20,"Local",IF(E20=F20,"Empate","Visitante")) | H20: =E20-F20 | J20: D | K20: 1 | L20: Turquía | M20: =(Q20*3)+R20 | N20: =O20-P20 | O20: =Z20+AA20 | P20: =AB20+AC20 | Q20: =T20+U20 | R20: =V20+W20 | S20: =X20+Y20 | T20: =COUNTIFS(C:C,L20,G:G,"Local") | U20: =COUNTIFS(D:D,L20,G:G,"Visitante") | V20: =COUNTIFS(C:C,L20,G:G,"Empate") | W20: =COUNTIFS(D:D,L20,G:G,"Empate") | X20: =COUNTIFS(C:C,L20,G:G,"Visitante") | Y20: =COUNTIFS(D:D,L20,G:G,"Local") | Z20: =SUMIF(C:C,L20,E:E) | AA20: =SUMIF(D:D,L20,F:F) | AB20: =SUMIF(C:C,L20,F:F) | AC20: =SUMIF(D:D,L20,E:E)
A21: 20 | B21: D | C21: Australia | D21: Turquía | E21: 1 | F21: 3 | G21: =IF(E21>F21,"Local",IF(E21=F21,"Empate","Visitante")) | H21: =E21-F21 | K21: 2 | L21: Estados Unidos | M21: =(Q21*3)+R21 | N21: =O21-P21 | O21: =Z21+AA21 | P21: =AB21+AC21 | Q21: =T21+U21 | R21: =V21+W21 | S21: =X21+Y21 | T21: =COUNTIFS(C:C,L21,G:G,"Local") | U21: =COUNTIFS(D:D,L21,G:G,"Visitante") | V21: =COUNTIFS(C:C,L21,G:G,"Empate") | W21: =COUNTIFS(D:D,L21,G:G,"Empate") | X21: =COUNTIFS(C:C,L21,G:G,"Visitante") | Y21: =COUNTIFS(D:D,L21,G:G,"Local") | Z21: =SUMIF(C:C,L21,E:E) | AA21: =SUMIF(D:D,L21,F:F) | AB21: =SUMIF(C:C,L21,F:F) | AC21: =SUMIF(D:D,L21,E:E)
A22: 21 | B22: D | C22: Estados Unidos | D22: Australia | E22: 2 | F22: 2 | G22: =IF(E22>F22,"Local",IF(E22=F22,"Empate","Visitante")) | H22: =E22-F22 | K22: 3 | L22: Australia | M22: =(Q22*3)+R22 | N22: =O22-P22 | O22: =Z22+AA22 | P22: =AB22+AC22 | Q22: =T22+U22 | R22: =V22+W22 | S22: =X22+Y22 | T22: =COUNTIFS(C:C,L22,G:G,"Local") | U22: =COUNTIFS(D:D,L22,G:G,"Visitante") | V22: =COUNTIFS(C:C,L22,G:G,"Empate") | W22: =COUNTIFS(D:D,L22,G:G,"Empate") | X22: =COUNTIFS(C:C,L22,G:G,"Visitante") | Y22: =COUNTIFS(D:D,L22,G:G,"Local") | Z22: =SUMIF(C:C,L22,E:E) | AA22: =SUMIF(D:D,L22,F:F) | AB22: =SUMIF(C:C,L22,F:F) | AC22: =SUMIF(D:D,L22,E:E)
A23: 22 | B23: D | C23: Turquía | D23: Paraguay | E23: 3 | F23: 1 | G23: =IF(E23>F23,"Local",IF(E23=F23,"Empate","Visitante")) | H23: =E23-F23 | K23: 4 | L23: Paraguay | M23: =(Q23*3)+R23 | N23: =O23-P23 | O23: =Z23+AA23 | P23: =AB23+AC23 | Q23: =T23+U23 | R23: =V23+W23 | S23: =X23+Y23 | T23: =COUNTIFS(C:C,L23,G:G,"Local") | U23: =COUNTIFS(D:D,L23,G:G,"Visitante") | V23: =COUNTIFS(C:C,L23,G:G,"Empate") | W23: =COUNTIFS(D:D,L23,G:G,"Empate") | X23: =COUNTIFS(C:C,L23,G:G,"Visitante") | Y23: =COUNTIFS(D:D,L23,G:G,"Local") | Z23: =SUMIF(C:C,L23,E:E) | AA23: =SUMIF(D:D,L23,F:F) | AB23: =SUMIF(C:C,L23,F:F) | AC23: =SUMIF(D:D,L23,E:E)
A24: 23 | B24: D | C24: Turquía | D24: Estados Unidos | E24: 2 | F24: 1 | G24: =IF(E24>F24,"Local",IF(E24=F24,"Empate","Visitante")) | H24: =E24-F24
A25: 24 | B25: D | C25: Paraguay | D25: Australia | E25: 1 | F25: 1 | G25: =IF(E25>F25,"Local",IF(E25=F25,"Empate","Visitante")) | H25: =E25-F25 | J25: Grupo | K25: Posición | L25: Equipo | M25: Puntos | N25: Diferencia | O25: GF | P25: GC | Q25: Victorias | R25: Empates | S25: Derrotas | T25: Victorias_L | U25: Victorias_V | V25: Empates_L | W25: Empates_V | X25: Derrotas_L | Y25: Derrotas_V | Z25: GF_L | AA25: GF_V | AB25: GC_L | AC25: GC_V
A26: 25 | B26: E | C26: Alemania | D26: Curazao | E26: 6 | F26: 0 | G26: =IF(E26>F26,"Local",IF(E26=F26,"Empate","Visitante")) | H26: =E26-F26 | J26: E | K26: 1 | L26: Alemania | M26: =(Q26*3)+R26 | N26: =O26-P26 | O26: =Z26+AA26 | P26: =AB26+AC26 | Q26: =T26+U26 | R26: =V26+W26 | S26: =X26+Y26 | T26: =COUNTIFS(C:C,L26,G:G,"Local") | U26: =COUNTIFS(D:D,L26,G:G,"Visitante") | V26: =COUNTIFS(C:C,L26,G:G,"Empate") | W26: =COUNTIFS(D:D,L26,G:G,"Empate") | X26: =COUNTIFS(C:C,L26,G:G,"Visitante") | Y26: =COUNTIFS(D:D,L26,G:G,"Local") | Z26: =SUMIF(C:C,L26,E:E) | AA26: =SUMIF(D:D,L26,F:F) | AB26: =SUMIF(C:C,L26,F:F) | AC26: =SUMIF(D:D,L26,E:E)
A27: 26 | B27: E | C27: Costa de Marfil | D27: Ecuador | E27: 2 | F27: 2 | G27: =IF(E27>F27,"Local",IF(E27=F27,"Empate","Visitante")) | H27: =E27-F27 | K27: 2 | L27: Ecuador | M27: =(Q27*3)+R27 | N27: =O27-P27 | O27: =Z27+AA27 | P27: =AB27+AC27 | Q27: =T27+U27 | R27: =V27+W27 | S27: =X27+Y27 | T27: =COUNTIFS(C:C,L27,G:G,"Local") | U27: =COUNTIFS(D:D,L27,G:G,"Visitante") | V27: =COUNTIFS(C:C,L27,G:G,"Empate") | W27: =COUNTIFS(D:D,L27,G:G,"Empate") | X27: =COUNTIFS(C:C,L27,G:G,"Visitante") | Y27: =COUNTIFS(D:D,L27,G:G,"Local") | Z27: =SUMIF(C:C,L27,E:E) | AA27: =SUMIF(D:D,L27,F:F) | AB27: =SUMIF(C:C,L27,F:F) | AC27: =SUMIF(D:D,L27,E:E)
A28: 27 | B28: E | C28: Alemania | D28: Costa de Marfil | E28: 3 | F28: 1 | G28: =IF(E28>F28,"Local",IF(E28=F28,"Empate","Visitante")) | H28: =E28-F28 | K28: 3 | L28: Costa de Marfil | M28: =(Q28*3)+R28 | N28: =O28-P28 | O28: =Z28+AA28 | P28: =AB28+AC28 | Q28: =T28+U28 | R28: =V28+W28 | S28: =X28+Y28 | T28: =COUNTIFS(C:C,L28,G:G,"Local") | U28: =COUNTIFS(D:D,L28,G:G,"Visitante") | V28: =COUNTIFS(C:C,L28,G:G,"Empate") | W28: =COUNTIFS(D:D,L28,G:G,"Empate") | X28: =COUNTIFS(C:C,L28,G:G,"Visitante") | Y28: =COUNTIFS(D:D,L28,G:G,"Local") | Z28: =SUMIF(C:C,L28,E:E) | AA28: =SUMIF(D:D,L28,F:F) | AB28: =SUMIF(C:C,L28,F:F) | AC28: =SUMIF(D:D,L28,E:E)
A29: 28 | B29: E | C29: Ecuador | D29: Curazao | E29: 3 | F29: 0 | G29: =IF(E29>F29,"Local",IF(E29=F29,"Empate","Visitante")) | H29: =E29-F29 | K29: 4 | L29: Curazao | M29: =(Q29*3)+R29 | N29: =O29-P29 | O29: =Z29+AA29 | P29: =AB29+AC29 | Q29: =T29+U29 | R29: =V29+W29 | S29: =X29+Y29 | T29: =COUNTIFS(C:C,L29,G:G,"Local") | U29: =COUNTIFS(D:D,L29,G:G,"Visitante") | V29: =COUNTIFS(C:C,L29,G:G,"Empate") | W29: =COUNTIFS(D:D,L29,G:G,"Empate") | X29: =COUNTIFS(C:C,L29,G:G,"Visitante") | Y29: =COUNTIFS(D:D,L29,G:G,"Local") | Z29: =SUMIF(C:C,L29,E:E) | AA29: =SUMIF(D:D,L29,F:F) | AB29: =SUMIF(C:C,L29,F:F) | AC29: =SUMIF(D:D,L29,E:E)
A30: 29 | B30: E | C30: Curazao | D30: Costa de Marfil | E30: 1 | F30: 2 | G30: =IF(E30>F30,"Local",IF(E30=F30,"Empate","Visitante")) | H30: =E30-F30
A31: 30 | B31: E | C31: Ecuador | D31: Alemania | E31: 2 | F31: 2 | G31: =IF(E31>F31,"Local",IF(E31=F31,"Empate","Visitante")) | H31: =E31-F31 | J31: Grupo | K31: Posición | L31: Equipo | M31: Puntos | N31: Diferencia | O31: GF | P31: GC | Q31: Victorias | R31: Empates | S31: Derrotas | T31: Victorias_L | U31: Victorias_V | V31: Empates_L | W31: Empates_V | X31: Derrotas_L | Y31: Derrotas_V | Z31: GF_L | AA31: GF_V | AB31: GC_L | AC31: GC_V
A32: 31 | B32: F | C32: Países Bajos | D32: Japón | E32: 2 | F32: 0 | G32: =IF(E32>F32,"Local",IF(E32=F32,"Empate","Visitante")) | H32: =E32-F32 | J32: F | K32: 1 | L32: Países Bajos | M32: =(Q32*3)+R32 | N32: =O32-P32 | O32: =Z32+AA32 | P32: =AB32+AC32 | Q32: =T32+U32 | R32: =V32+W32 | S32: =X32+Y32 | T32: =COUNTIFS(C:C,L32,G:G,"Local") | U32: =COUNTIFS(D:D,L32,G:G,"Visitante") | V32: =COUNTIFS(C:C,L32,G:G,"Empate") | W32: =COUNTIFS(D:D,L32,G:G,"Empate") | X32: =COUNTIFS(C:C,L32,G:G,"Visitante") | Y32: =COUNTIFS(D:D,L32,G:G,"Local") | Z32: =SUMIF(C:C,L32,E:E) | AA32: =SUMIF(D:D,L32,F:F) | AB32: =SUMIF(C:C,L32,F:F) | AC32: =SUMIF(D:D,L32,E:E)
A33: 32 | B33: F | C33: Suecia | D33: Túnez | E33: 1 | F33: 1 | G33: =IF(E33>F33,"Local",IF(E33=F33,"Empate","Visitante")) | H33: =E33-F33 | K33: 2 | L33: Japón | M33: =(Q33*3)+R33 | N33: =O33-P33 | O33: =Z33+AA33 | P33: =AB33+AC33 | Q33: =T33+U33 | R33: =V33+W33 | S33: =X33+Y33 | T33: =COUNTIFS(C:C,L33,G:G,"Local") | U33: =COUNTIFS(D:D,L33,G:G,"Visitante") | V33: =COUNTIFS(C:C,L33,G:G,"Empate") | W33: =COUNTIFS(D:D,L33,G:G,"Empate") | X33: =COUNTIFS(C:C,L33,G:G,"Visitante") | Y33: =COUNTIFS(D:D,L33,G:G,"Local") | Z33: =SUMIF(C:C,L33,E:E) | AA33: =SUMIF(D:D,L33,F:F) | AB33: =SUMIF(C:C,L33,F:F) | AC33: =SUMIF(D:D,L33,E:E)
A34: 33 | B34: F | C34: Países Bajos | D34: Suecia | E34: 1 | F34: 0 | G34: =IF(E34>F34,"Local",IF(E34=F34,"Empate","Visitante")) | H34: =E34-F34 | K34: 3 | L34: Suecia | M34: =(Q34*3)+R34 | N34: =O34-P34 | O34: =Z34+AA34 | P34: =AB34+AC34 | Q34: =T34+U34 | R34: =V34+W34 | S34: =X34+Y34 | T34: =COUNTIFS(C:C,L34,G:G,"Local") | U34: =COUNTIFS(D:D,L34,G:G,"Visitante") | V34: =COUNTIFS(C:C,L34,G:G,"Empate") | W34: =COUNTIFS(D:D,L34,G:G,"Empate") | X34: =COUNTIFS(C:C,L34,G:G,"Visitante") | Y34: =COUNTIFS(D:D,L34,G:G,"Local") | Z34: =SUMIF(C:C,L34,E:E) | AA34: =SUMIF(D:D,L34,F:F) | AB34: =SUMIF(C:C,L34,F:F) | AC34: =SUMIF(D:D,L34,E:E)
A35: 34 | B35: F | C35: Túnez | D35: Japón | E35: 1 | F35: 3 | G35: =IF(E35>F35,"Local",IF(E35=F35,"Empate","Visitante")) | H35: =E35-F35 | K35: 4 | L35: Túnez | M35: =(Q35*3)+R35 | N35: =O35-P35 | O35: =Z35+AA35 | P35: =AB35+AC35 | Q35: =T35+U35 | R35: =V35+W35 | S35: =X35+Y35 | T35: =COUNTIFS(C:C,L35,G:G,"Local") | U35: =COUNTIFS(D:D,L35,G:G,"Visitante") | V35: =COUNTIFS(C:C,L35,G:G,"Empate") | W35: =COUNTIFS(D:D,L35,G:G,"Empate") | X35: =COUNTIFS(C:C,L35,G:G,"Visitante") | Y35: =COUNTIFS(D:D,L35,G:G,"Local") | Z35: =SUMIF(C:C,L35,E:E) | AA35: =SUMIF(D:D,L35,F:F) | AB35: =SUMIF(C:C,L35,F:F) | AC35: =SUMIF(D:D,L35,E:E)
A36: 35 | B36: F | C36: Japón | D36: Suecia | E36: 2 | F36: 1 | G36: =IF(E36>F36,"Local",IF(E36=F36,"Empate","Visitante")) | H36: =E36-F36
A37: 36 | B37: F | C37: Túnez | D37: Países Bajos | E37: 0 | F37: 2 | G37: =IF(E37>F37,"Local",IF(E37=F37,"Empate","Visitante")) | H37: =E37-F37 | J37: Grupo | K37: Posición | L37: Equipo | M37: Puntos | N37: Diferencia | O37: GF | P37: GC | Q37: Victorias | R37: Empates | S37: Derrotas | T37: Victorias_L | U37: Victorias_V | V37: Empates_L | W37: Empates_V | X37: Derrotas_L | Y37: Derrotas_V | Z37: GF_L | AA37: GF_V | AB37: GC_L | AC37: GC_V
A38: 37 | B38: G | C38: Bélgica | D38: Egipto | E38: 1 | F38: 0 | G38: =IF(E38>F38,"Local",IF(E38=F38,"Empate","Visitante")) | H38: =E38-F38 | J38: G | K38: 1 | L38: Bélgica | M38: =(Q38*3)+R38 | N38: =O38-P38 | O38: =Z38+AA38 | P38: =AB38+AC38 | Q38: =T38+U38 | R38: =V38+W38 | S38: =X38+Y38 | T38: =COUNTIFS(C:C,L38,G:G,"Local") | U38: =COUNTIFS(D:D,L38,G:G,"Visitante") | V38: =COUNTIFS(C:C,L38,G:G,"Empate") | W38: =COUNTIFS(D:D,L38,G:G,"Empate") | X38: =COUNTIFS(C:C,L38,G:G,"Visitante") | Y38: =COUNTIFS(D:D,L38,G:G,"Local") | Z38: =SUMIF(C:C,L38,E:E) | AA38: =SUMIF(D:D,L38,F:F) | AB38: =SUMIF(C:C,L38,F:F) | AC38: =SUMIF(D:D,L38,E:E)
A39: 38 | B39: G | C39: Irán | D39: Nueva Zelanda | E39: 0 | F39: 0 | G39: =IF(E39>F39,"Local",IF(E39=F39,"Empate","Visitante")) | H39: =E39-F39 | K39: 2 | L39: Egipto | M39: =(Q39*3)+R39 | N39: =O39-P39 | O39: =Z39+AA39 | P39: =AB39+AC39 | Q39: =T39+U39 | R39: =V39+W39 | S39: =X39+Y39 | T39: =COUNTIFS(C:C,L39,G:G,"Local") | U39: =COUNTIFS(D:D,L39,G:G,"Visitante") | V39: =COUNTIFS(C:C,L39,G:G,"Empate") | W39: =COUNTIFS(D:D,L39,G:G,"Empate") | X39: =COUNTIFS(C:C,L39,G:G,"Visitante") | Y39: =COUNTIFS(D:D,L39,G:G,"Local") | Z39: =SUMIF(C:C,L39,E:E) | AA39: =SUMIF(D:D,L39,F:F) | AB39: =SUMIF(C:C,L39,F:F) | AC39: =SUMIF(D:D,L39,E:E)
A40: 39 | B40: G | C40: Bélgica | D40: Irán | E40: 4 | F40: 1 | G40: =IF(E40>F40,"Local",IF(E40=F40,"Empate","Visitante")) | H40: =E40-F40 | K40: 3 | L40: Nueva Zelanda | M40: =(Q40*3)+R40 | N40: =O40-P40 | O40: =Z40+AA40 | P40: =AB40+AC40 | Q40: =T40+U40 | R40: =V40+W40 | S40: =X40+Y40 | T40: =COUNTIFS(C:C,L40,G:G,"Local") | U40: =COUNTIFS(D:D,L40,G:G,"Visitante") | V40: =COUNTIFS(C:C,L40,G:G,"Empate") | W40: =COUNTIFS(D:D,L40,G:G,"Empate") | X40: =COUNTIFS(C:C,L40,G:G,"Visitante") | Y40: =COUNTIFS(D:D,L40,G:G,"Local") | Z40: =SUMIF(C:C,L40,E:E) | AA40: =SUMIF(D:D,L40,F:F) | AB40: =SUMIF(C:C,L40,F:F) | AC40: =SUMIF(D:D,L40,E:E)
...

Sheet Bracket_Hugo
A1: Dieciseisavos | D1: Octavos | G1: Cuartos | J1: Semifinal | M1: Tercero puesto | P1: Final | S1: Tercero | T1: Campeón
A2: 74 | B2: 1E | C2: Alemania | D2: 89 | E2: W74 | F2: Alemania | G2: 97 | H2: W89 | I2: Francia | J2: 101 | K2: W97 | L2: Francia | M2: 103 | N2: L101 | O2: Bélgica | P2: 104 | Q2: W101 | R2: Francia | S2: Brasil | T2: Francia
B3: 3ABCDF | C3: Escocia | E3: W77 | F3: Francia | H3: W90 | I3: Países Bajos | K3: W98 | L3: Bélgica | N3: L102 | O3: Brasil | Q3: W102 | R3: España
A4: 77 | B4: 1I | C4: Francia | D4: 90 | E4: W73 | F4: Canadá | G4: 98 | H4: W93 | I4: Colombia | J4: 102 | K4: W99 | L4: Brasil
B5: 3CDFGH | C5: Arabia Saudi | E5: W75 | F5: Países Bajos | H5: W94 | I5: Bélgica | K5: W100 | L5: España
A6: 73 | B6: 2A | C6: Sudáfrica | D6: 93 | E6: W83 | F6: Colombia | G6: 99 | H6: W91 | I6: Brasil
B7: 2B | C7: Canadá | E7: W84 | F7: Uruguay | H7: W92 | I7: Inglaterra
A8: 75 | B8: 1F | C8: Países Bajos | D8: 94 | E8: W81 | F8: Turquía | G8: 100 | H8: W95 | I8: España
B9: 2C | C9: Marruecos | E9: W82 | F9: Bélgica | H9: W96 | I9: Portugal
A10: 83 | B10: 2K | C10: Colombia | D10: 91 | E10: W76 | F10: Brasil
B11: 2L | C11: Croacia | E11: W78 | F11: Ecuador
A12: 84 | B12: 1H | C12: Uruguay | D12: 92 | E12: W79 | F12: México
B13: 2J | C13: Austria | E13: W80 | F13: Inglaterra
A14: 81 | B14: 1D | C14: Turquía | D14: 95 | E14: W86 | F14: España
B15: 3BEFIJ | C15: Bosnia y Herzegovina | E15: W88 | F15: Estados Unidos
A16: 82 | B16: 1G | C16: Bélgica | D16: 96 | E16: W85 | F16: Suiza
B17: 3AEHIJ | C17: República Checa | E17: W87 | F17: Portugal
A18: 76 | B18: 1C | C18: Brasil
B19: 2F | C19: Japón
A20: 78 | B20: 2E | C20: Ecuador
B21: 2I | C21: Noruega
A22: 79 | B22: 1A | C22: México
B23: 3CEFHI | C23: Costa de Marfil
A24: 80 | B24: 1L | C24: Inglaterra
B25: 3EHIJK | C25: RD Congo
A26: 86 | B26: 1J | C26: Argentina
B27: 2H | C27: España
A28: 88 | B28: 2D | C28: Estados Unidos
B29: 2G | C29: Egipto
A30: 85 | B30: 1B | C30: Suiza
B31: 3EFGIJ | C31: Senegal
A32: 87 | B32: 1K | C32: Portugal
B33: 3DEIJL | C33: Ghana

Sheet Playoffs_Hugo
A1: Dieciseisavos | B1: Octavos | C1: Cuartos | D1: Semifinal | E1: Tercero | F1: Final | G1: Campeón
A2: Alemania | B2: Alemania | C2: Francia | D2: Francia | E2: Brasil | F2: Francia | G2: Francia
A3: Escocia | B3: Francia | C3: Países Bajos | D3: Bélgica | F3: España
A4: Francia | B4: Canadá | C4: Colombia | D4: Brasil
A5: Arabia Saudi | B5: Países Bajos | C5: Bélgica | D5: España
A6: Sudáfrica | B6: Colombia | C6: Brasil
A7: Canadá | B7: Uruguay | C7: Inglaterra
A8: Países Bajos | B8: Turquía | C8: España
A9: Marruecos | B9: Bélgica | C9: Portugal
A10: Colombia | B10: Brasil
A11: Croacia | B11: Ecuador
A12: Uruguay | B12: México
A13: Austria | B13: Inglaterra
A14: Turquía | B14: España
A15: Bosnia y Herzegovina | B15: Estados Unidos
A16: Bélgica | B16: Suiza
A17: República Checa | B17: Portugal
A18: Brasil
A19: Japón
A20: Ecuador
A21: Noruega
A22: México
A23: Costa de Marfil
A24: Inglaterra
A25: RD Congo
A26: Argentina
A27: España
A28: Estados Unidos
A29: Egipto
... A33: Ghana

Sheet Playoffs_Predicciones_Hugo
A1: PARTIDOS DE DIECISEISAVOS
A2: Partido | B2: Local | C2: Visitante | D2: G_Local | E2: G_Visitante | F2: Resultado | G2: Diferencia
A3: 1 | B3: Alemania | C3: Paraguay | D3: 5 | E3: 0 | F3: =IF(D3>E3,"Local",IF(D3=E3,"Empate","Visitante")) | G3: =D3-E3
A4: 2 | B4: Francia | C4: Suecia | D4: 4 | E4: 1 | F4: =IF(D4>E4,"Local",IF(D4=E4,"Empate","Visitante")) | G4: =D4-E4
A5: 3 | B5: Sudáfrica | C5: Canadá | D5: 1 | E5: 3 | F5: =IF(D5>E5,"Local",IF(D5=E5,"Empate","Visitante")) | G5: =D5-E5
A6: 4 | B6: Países Bajos | C6: Marruecos | D6: 3 | E6: 1 | F6: =IF(D6>E6,"Local",IF(D6=E6,"Empate","Visitante")) | G6: =D6-E6
A7: 5 | B7: Portugal | C7: Croacia | D7: 2 | E7: 1 | F7: =IF(D7>E7,"Local",IF(D7=E7,"Empate","Visitante")) | G7: =D7-E7
A8: 6 | B8: España | C8: Austria | D8: 4 | E8: 1 | F8: =IF(D8>E8,"Local",IF(D8=E8,"Empate","Visitante")) | G8: =D8-E8
A9: 7 | B9: Estados Unidos | C9: Bosnia y Herzegovina | D9: 4 | E9: 2 | F9: =IF(D9>E9,"Local",IF(D9=E9,"Empate","Visitante")) | G9: =D9-E9
A10: 8 | B10: Bélgica | C10: Senegal | D10: 2 | E10: 2 | F10: =IF(D10>E10,"Local",IF(D10=E10,"Empate","Visitante")) | G10: =D10-E10
A11: 9 | B11: Brasil | C11: Japón | D11: 4 | E11: 2 | F11: =IF(D11>E11,"Local",IF(D11=E11,"Empate","Visitante")) | G11: =D11-E11
A12: 10 | B12: Costa de Marfil | C12: Noruega | D12: 1 | E12: 2 | F12: =IF(D12>E12,"Local",IF(D12=E12,"Empate","Visitante")) | G12: =D12-E12
A13: 11 | B13: México | C13: Ecuador | D13: 3 | E13: 0 | F13: =IF(D13>E13,"Local",IF(D13=E13,"Empate","Visitante")) | G13: =D13-E13
A14: 12 | B14: Inglaterra | C14: RD Congo | D14: 2 | E14: 1 | F14: =IF(D14>E14,"Local",IF(D14=E14,"Empate","Visitante")) | G14: =D14-E14
... A18: 16 | B18: Colombia | C18: Ghana | D18: 2 | E18: 0 | F18: =IF(D18>E18,"Local",IF(D18=E18,"Empate","Visitante")) | G18: =D18-E18
A20: PARTIDOS DE OCTAVOS DE FINAL
A21: Partido | B21: Local | C21: Visitante | D21: G_Local | E21: G_Visitante | F21: Resultado | G21: Diferencia
A22: 1 | B22: Paraguay | C22: Francia | D22: 0 | E22: 3 | F22: =IF(D22>E22,"Local",IF(D22=E22,"Empate","Visitante")) | G22: =D22-E22
A23: 2 | B23: Canadá | C23: Marruecos | D23: 1 | E23: 1 | F23: =IF(D23>E23,"Local",IF(D23=E23,"Empate","Visitante")) | G23: =D23-E23
A24: 3 | B24: Portugal | C24: España | D24: 1 | E24: 2 | F24: =IF(D24>E24,"Local",IF(D24=E24,"Empate","Visitante")) | G24: =D24-E24
A25: 4 | B25: Estados Unidos | C25: Bélgica | D25: 3 | E25: 1 | F25: =IF(D25>E25,"Local",IF(D25=E25,"Empate","Visitante")) | G25: =D25-E25
A26: 5 | B26: Brasil | C26: Noruega | D26: 3 | E26: 2 | F26: =IF(D26>E26,"Local",IF(D26=E26,"Empate","Visitante")) | G26: =D26-E26
A27: 6 | B27: México | C27: Inglaterra | D27: 1 | E27: 1 | F27: =IF(D27>E27,"Local",IF(D27=E27,"Empate","Visitante")) | G27: =D27-E27
A28: 7 | B28: Argentina | C28: Egipto | D28: 2 | E28: 0 | F28: =IF(D28>E28,"Local",IF(D28=E28,"Empate","Visitante")) | G28: =D28-E28
A29: 8 | B29: Suiza | C29: Colombia | D29: 1 | E29: 2 | F29: =IF(D29>E29,"Local",IF(D29=E29,"Empate","Visitante")) | G29: =D29-E29
A31: PARTIDOS DE CUARTOS DE FINAL
A32: Partido | B32: Local | C32: Visitante | D32: G_Local | E32: G_Visitante | F32: Resultado | G32: Diferencia
A33: 1 | B33: Francia | C33: Marruecos | D33: 2 | E33: 1 | F33: =IF(D33>E33,"Local",IF(D33=E33,"Empate","Visitante")) | G33: =D33-E33
A34: 2 | B34: España | C34: Bélgica | D34: 1 | E34: 2 | F34: =IF(D34>E34,"Local",IF(D34=E34,"Empate","Visitante")) | G34: =D34-E34
A35: 3 | B35: Noruega | C35: Inglaterra | D35: 3 | E35: 1 | F35: =IF(D35>E35,"Local",IF(D35=E35,"Empate","Visitante")) | G35: =D35-E35
A36: 4 | B36: Argentina | C36: Suiza | D36: 2 | E36: 1 | F36: =IF(D36>E36,"Local",IF(D36=E36,"Empate","Visitante")) | G36: =D36-E36
A38: PARTIDOS DE SEMIFINAL
A39: Partido | B39: Local | C39: Visitante | D39: G_Local | E39: G_Visitante | F39: Resultado | G39: Diferencia
A40: 1 | B40: Francia | C40: España | D40: 2 | E40: 0 | F40: =IF(D40>E40,"Local",IF(D40=E40,"Empate","Visitante")) | G40: =D40-E40
A41: 2 | B41: Inglaterra | C41: Argentina | D41: 2 | E41: 1 | F41: =IF(D41>E41,"Local",IF(D41=E41,"Empate","Visitante")) | G41: =D41-E41
A43: PARTIDOS DE TERCEROS
A44: Partido | B44: Local | C44: Visitante | D44: G_Local | E44: G_Visitante | F44: Resultado | G44: Diferencia
A45: 1 | B45: Francia | C45: Inglaterra | D45: 2 | E45: 1 | F45: =IF(D45>E45,"Local",IF(D45=E45,"Empate","Visitante")) | G45: =D45-E45
A47: PARTIDOS DE FINAL
A48: Partido | B48: Local | C48: Visitante | D48: G_Local | E48: G_Visitante | F48: Resultado | G48: Diferencia
...

Sheet Predicciones_Oscar
A1: Partido | B1: Grupo | C1: Local | D1: Visitante | E1: G_Local | F1: G_Visitante | G1: Resultado | H1: Diferencia | J1: Grupo | K1: Posición | L1: Equipo | M1: Puntos | N1: Diferencia | O1: GF | P1: GC | Q1: Victorias | R1: Empates | S1: Derrotas | T1: Victorias_L | U1: Victorias_V | V1: Empates_L | W1: Empates_V | X1: Derrotas_L | Y1: Derrotas_V | Z1: GF_L | AA1: GF_V | AB1: GC_L | AC1: GC_V
A2: 1 | B2: A | C2: México | D2: Sudáfrica | E2: 2 | F2: 1 | G2: =IF(E2>F2,"Local",IF(E2=F2,"Empate","Visitante")) | H2: =E2-F2 | J2: A | K2: 1 | L2: México | M2: =(Q2*3)+R2 | N2: =O2-P2 | O2: =Z2+AA2 | P2: =AB2+AC2 | Q2: =T2+U2 | R2: =V2+W2 | S2: =X2+Y2 | T2: =COUNTIFS(C:C,L2,G:G,"Local") | U2: =COUNTIFS(D:D,L2,G:G,"Visitante") | V2: =COUNTIFS(C:C,L2,G:G,"Empate") | W2: =COUNTIFS(D:D,L2,G:G,"Empate") | X2: =COUNTIFS(C:C,L2,G:G,"Visitante") | Y2: =COUNTIFS(D:D,L2,G:G,"Local") | Z2: =SUMIF(C:C,L2,E:E) | AA2: =SUMIF(D:D,L2,F:F) | AB2: =SUMIF(C:C,L2,F:F) | AC2: =SUMIF(D:D,L2,E:E)
A3: 2 | B3: A | C3: Corea del Sur | D3: República Checa | E3: 1 | F3: 1 | G3: =IF(E3>F3,"Local",IF(E3=F3,"Empate","Visitante")) | H3: =E3-F3 | K3: 2 | L3: República Checa | M3: =(Q3*3)+R3 | N3: =O3-P3 | O3: =Z3+AA3 | P3: =AB3+AC3 | Q3: =T3+U3 | R3: =V3+W3 | S3: =X3+Y3 | T3: =COUNTIFS(C:C,L3,G:G,"Local") | U3: =COUNTIFS(D:D,L3,G:G,"Visitante") | V3: =COUNTIFS(C:C,L3,G:G,"Empate") | W3: =COUNTIFS(D:D,L3,G:G,"Empate") | X3: =COUNTIFS(C:C,L3,G:G,"Visitante") | Y3: =COUNTIFS(D:D,L3,G:G,"Local") | Z3: =SUMIF(C:C,L3,E:E) | AA3: =SUMIF(D:D,L3,F:F) | AB3: =SUMIF(C:C,L3,F:F) | AC3: =SUMIF(D:D,L3,E:E)
A4: 3 | B4: A | C4: República Checa | D4: Sudáfrica | E4: 2 | F4: 0 | G4: =IF(E4>F4,"Local",IF(E4=F4,"Empate","Visitante")) | H4: =E4-F4 | K4: 3 | L4: Corea del Sur | M4: =(Q4*3)+R4 | N4: =O4-P4 | O4: =Z4+AA4 | P4: =AB4+AC4 | Q4: =T4+U4 | R4: =V4+W4 | S4: =X4+Y4 | T4: =COUNTIFS(C:C,L4,G:G,"Local") | U4: =COUNTIFS(D:D,L4,G:G,"Visitante") | V4: =COUNTIFS(C:C,L4,G:G,"Empate") | W4: =COUNTIFS(D:D,L4,G:G,"Empate") | X4: =COUNTIFS(C:C,L4,G:G,"Visitante") | Y4: =COUNTIFS(D:D,L4,G:G,"Local") | Z4: =SUMIF(C:C,L4,E:E) | AA4: =SUMIF(D:D,L4,F:F) | AB4: =SUMIF(C:C,L4,F:F) | AC4: =SUMIF(D:D,L4,E:E)
A5: 4 | B5: A | C5: México | D5: Corea del Sur | E5: 2 | F5: 1 | G5: =IF(E5>F5,"Local",IF(E5=F5,"Empate","Visitante")) | H5: =E5-F5 | K5: 4 | L5: Sudáfrica | M5: =(Q5*3)+R5 | N5: =O5-P5 | O5: =Z5+AA5 | P5: =AB5+AC5 | Q5: =T5+U5 | R5: =V5+W5 | S5: =X5+Y5 | T5: =COUNTIFS(C:C,L5,G:G,"Local") | U5: =COUNTIFS(D:D,L5,G:G,"Visitante") | V5: =COUNTIFS(C:C,L5,G:G,"Empate") | W5: =COUNTIFS(D:D,L5,G:G,"Empate") | X5: =COUNTIFS(C:C,L5,G:G,"Visitante") | Y5: =COUNTIFS(D:D,L5,G:G,"Local") | Z5: =SUMIF(C:C,L5,E:E) | AA5: =SUMIF(D:D,L5,F:F) | AB5: =SUMIF(C:C,L5,F:F) | AC5: =SUMIF(D:D,L5,E:E)
A6: 5 | B6: A | C6: República Checa | D6: México | E6: 1 | F6: 1 | G6: =IF(E6>F6,"Local",IF(E6=F6,"Empate","Visitante")) | H6: =E6-F6
A7: 6 | B7: A | C7: Sudáfrica | D7: Corea del Sur | E7: 1 | F7: 2 | G7: =IF(E7>F7,"Local",IF(E7=F7,"Empate","Visitante")) | H7: =E7-F7 | J7: Grupo | K7: Posición | L7: Equipo | M7: Puntos | N7: Diferencia | O7: GF | P7: GC | Q7: Victorias | R7: Empates | S7: Derrotas | T7: Victorias_L | U7: Victorias_V | V7: Empates_L | W7: Empates_V | X7: Derrotas_L | Y7: Derrotas_V | Z7: GF_L | AA7: GF_V | AB7: GC_L | AC7: GC_V
A8: 7 | B8: B | C8: Canadá | D8: Bosnia y Herzegovina | E8: 2 | F8: 1 | G8: =IF(E8>F8,"Local",IF(E8=F8,"Empate","Visitante")) | H8: =E8-F8 | J8: B | K8: 1 | L8: Suiza | M8: =(Q8*3)+R8 | N8: =O8-P8 | O8: =Z8+AA8 | P8: =AB8+AC8 | Q8: =T8+U8 | R8: =V8+W8 | S8: =X8+Y8 | T8: =COUNTIFS(C:C,L8,G:G,"Local") | U8: =COUNTIFS(D:D,L8,G:G,"Visitante") | V8: =COUNTIFS(C:C,L8,G:G,"Empate") | W8: =COUNTIFS(D:D,L8,G:G,"Empate") | X8: =COUNTIFS(C:C,L8,G:G,"Visitante") | Y8: =COUNTIFS(D:D,L8,G:G,"Local") | Z8: =SUMIF(C:C,L8,E:E) | AA8: =SUMIF(D:D,L8,F:F) | AB8: =SUMIF(C:C,L8,F:F) | AC8: =SUMIF(D:D,L8,E:E)
A9: 8 | B9: B | C9: Catar | D9: Suiza | E9: 0 | F9: 2 | G9: =IF(E9>F9,"Local",IF(E9=F9,"Empate","Visitante")) | H9: =E9-F9 | K9: 2 | L9: Canadá | M9: =(Q9*3)+R9 | N9: =O9-P9 | O9: =Z9+AA9 | P9: =AB9+AC9 | Q9: =T9+U9 | R9: =V9+W9 | S9: =X9+Y9 | T9: =COUNTIFS(C:C,L9,G:G,"Local") | U9: =COUNTIFS(D:D,L9,G:G,"Visitante") | V9: =COUNTIFS(C:C,L9,G:G,"Empate") | W9: =COUNTIFS(D:D,L9,G:G,"Empate") | X9: =COUNTIFS(C:C,L9,G:G,"Visitante") | Y9: =COUNTIFS(D:D,L9,G:G,"Local") | Z9: =SUMIF(C:C,L9,E:E) | AA9: =SUMIF(D:D,L9,F:F) | AB9: =SUMIF(C:C,L9,F:F) | AC9: =SUMIF(D:D,L9,E:E)
A10: 9 | B10: B | C10: Suiza | D10: Bosnia y Herzegovina | E10: 2 | F10: 0 | G10: =IF(E10>F10,"Local",IF(E10=F10,"Empate","Visitante")) | H10: =E10-F10 | K10: 3 | L10: Bosnia y Herzegovina | M10: =(Q10*3)+R10 | N10: =O10-P10 | O10: =Z10+AA10 | P10: =AB10+AC10 | Q10: =T10+U10 | R10: =V10+W10 | S10: =X10+Y10 | T10: =COUNTIFS(C:C,L10,G:G,"Local") | U10: =COUNTIFS(D:D,L10,G:G,"Visitante") | V10: =COUNTIFS(C:C,L10,G:G,"Empate") | W10: =COUNTIFS(D:D,L10,G:G,"Empate") | X10: =COUNTIFS(C:C,L10,G:G,"Visitante") | Y10: =COUNTIFS(D:D,L10,G:G,"Local") | Z10: =SUMIF(C:C,L10,E:E) | AA10: =SUMIF(D:D,L10,F:F) | AB10: =SUMIF(C:C,L10,F:F) | AC10: =SUMIF(D:D,L10,E:E)
A11: 10 | B11: B | C11: Canadá | D11: Catar | E11: 2 | F11: 0 | G11: =IF(E11>F11,"Local",IF(E11=F11,"Empate","Visitante")) | H11: =E11-F11 | K11: 4 | L11: Catar | M11: =(Q11*3)+R11 | N11: =O11-P11 | O11: =Z11+AA11 | P11: =AB11+AC11 | Q11: =T11+U11 | R11: =V11+W11 | S11: =X11+Y11 | T11: =COUNTIFS(C:C,L11,G:G,"Local") | U11: =COUNTIFS(D:D,L11,G:G,"Visitante") | V11: =COUNTIFS(C:C,L11,G:G,"Empate") | W11: =COUNTIFS(D:D,L11,G:G,"Empate") | X11: =COUNTIFS(C:C,L11,G:G,"Visitante") | Y11: =COUNTIFS(D:D,L11,G:G,"Local") | Z11: =SUMIF(C:C,L11,E:E) | AA11: =SUMIF(D:D,L11,F:F) | AB11: =SUMIF(C:C,L11,F:F) | AC11: =SUMIF(D:D,L11,E:E)
A12: 11 | B12: B | C12: Suiza | D12: Canadá | E12: 1 | F12: 1 | G12: =IF(E12>F12,"Local",IF(E12=F12,"Empate","Visitante")) | H12: =E12-F12
A13: 12 | B13: B | C13: Bosnia y Herzegovina | D13: Catar | E13: 2 | F13: 1 | G13: =IF(E13>F13,"Local",IF(E13=F13,"Empate","Visitante")) | H13: =E13-F13 | J13: Grupo | K13: Posición | L13: Equipo | M13: Puntos | N13: Diferencia | O13: GF | P13: GC | Q13: Victorias | R13: Empates | S13: Derrotas | T13: Victorias_L | U13: Victorias_V | V13: Empates_L | W13: Empates_V | X13: Derrotas_L | Y13: Derrotas_V | Z13: GF_L | AA13: GF_V | AB13: GC_L | AC13: GC_V
A14: 13 | B14: C | C14: Brasil | D14: Marruecos | E14: 2 | F14: 1 | G14: =IF(E14>F14,"Local",IF(E14=F14,"Empate","Visitante")) | H14: =E14-F14 | J14: C | K14: 1 | L14: Brasil | M14: =(Q14*3)+R14 | N14: =O14-P14 | O14: =Z14+AA14 | P14: =AB14+AC14 | Q14: =T14+U14 | R14: =V14+W14 | S14: =X14+Y14 | T14: =COUNTIFS(C:C,L14,G:G,"Local") | U14: =COUNTIFS(D:D,L14,G:G,"Visitante") | V14: =COUNTIFS(C:C,L14,G:G,"Empate") | W14: =COUNTIFS(D:D,L14,G:G,"Empate") | X14: =COUNTIFS(C:C,L14,G:G,"Visitante") | Y14: =COUNTIFS(D:D,L14,G:G,"Local") | Z14: =SUMIF(C:C,L14,E:E) | AA14: =SUMIF(D:D,L14,F:F) | AB14: =SUMIF(C:C,L14,F:F) | AC14: =SUMIF(D:D,L14,E:E)
A15: 14 | B15: C | C15: Haití | D15: Escocia | E15: 0 | F15: 2 | G15: =IF(E15>F15,"Local",IF(E15=F15,"Empate","Visitante")) | H15: =E15-F15 | K15: 2 | L15: Marruecos | M15: =(Q15*3)+R15 | N15: =O15-P15 | O15: =Z15+AA15 | P15: =AB15+AC15 | Q15: =T15+U15 | R15: =V15+W15 | S15: =X15+Y15 | T15: =COUNTIFS(C:C,L15,G:G,"Local") | U15: =COUNTIFS(D:D,L15,G:G,"Visitante") | V15: =COUNTIFS(C:C,L15,G:G,"Empate") | W15: =COUNTIFS(D:D,L15,G:G,"Empate") | X15: =COUNTIFS(C:C,L15,G:G,"Visitante") | Y15: =COUNTIFS(D:D,L15,G:G,"Local") | Z15: =SUMIF(C:C,L15,E:E) | AA15: =SUMIF(D:D,L15,F:F) | AB15: =SUMIF(C:C,L15,F:F) | AC15: =SUMIF(D:D,L15,E:E)
A16: 15 | B16: C | C16: Escocia | D16: Marruecos | E16: 1 | F16: 2 | G16: =IF(E16>F16,"Local",IF(E16=F16,"Empate","Visitante")) | H16: =E16-F16 | K16: 3 | L16: Escocia | M16: =(Q16*3)+R16 | N16: =O16-P16 | O16: =Z16+AA16 | P16: =AB16+AC16 | Q16: =T16+U16 | R16: =V16+W16 | S16: =X16+Y16 | T16: =COUNTIFS(C:C,L16,G:G,"Local") | U16: =COUNTIFS(D:D,L16,G:G,"Visitante") | V16: =COUNTIFS(C:C,L16,G:G,"Empate") | W16: =COUNTIFS(D:D,L16,G:G,"Empate") | X16: =COUNTIFS(C:C,L16,G:G,"Visitante") | Y16: =COUNTIFS(D:D,L16,G:G,"Local") | Z16: =SUMIF(C:C,L16,E:E) | AA16: =SUMIF(D:D,L16,F:F) | AB16: =SUMIF(C:C,L16,F:F) | AC16: =SUMIF(D:D,L16,E:E)
A17: 16 | B17: C | C17: Brasil | D17: Haití | E17: 4 | F17: 0 | G17: =IF(E17>F17,"Local",IF(E17=F17,"Empate","Visitante")) | H17: =E17-F17 | K17: 4 | L17: Haití | M17: =(Q17*3)+R17 | N17: =O17-P17 | O17: =Z17+AA17 | P17: =AB17+AC17 | Q17: =T17+U17 | R17: =V17+W17 | S17: =X17+Y17 | T17: =COUNTIFS(C:C,L17,G:G,"Local") | U17: =COUNTIFS(D:D,L17,G:G,"Visitante") | V17: =COUNTIFS(C:C,L17,G:G,"Empate") | W17: =COUNTIFS(D:D,L17,G:G,"Empate") | X17: =COUNTIFS(C:C,L17,G:G,"Visitante") | Y17: =COUNTIFS(D:D,L17,G:G,"Local") | Z17: =SUMIF(C:C,L17,E:E) | AA17: =SUMIF(D:D,L17,F:F) | AB17: =SUMIF(C:C,L17,F:F) | AC17: =SUMIF(D:D,L17,E:E)
A18: 17 | B18: C | C18: Escocia | D18: Brasil | E18: 1 | F18: 3 | G18: =IF(E18>F18,"Local",IF(E18=F18,"Empate","Visitante")) | H18: =E18-F18
A19: 18 | B19: C | C19: Marruecos | D19: Haití | E19: 3 | F19: 0 | G19: =IF(E19>F19,"Local",IF(E19=F19,"Empate","Visitante")) | H19: =E19-F19 | J19: Grupo | K19: Posición | L19: Equipo | M19: Puntos | N19: Diferencia | O19: GF | P19: GC | Q19: Victorias | R19: Empates | S19: Derrotas | T19: Victorias_L | U19: Victorias_V | V19: Empates_L | W19: Empates_V | X19: Derrotas_L | Y19: Derrotas_V | Z19: GF_L | AA19: GF_V | AB19: GC_L | AC19: GC_V
A20: 19 | B20: D | C20: Estados Unidos | D20: Paraguay | E20: 1 | F20: 2 | G20: =IF(E20>F20,"Local",IF(E20=F20,"Empate","Visitante")) | H20: =E20-F20 | J20: D | K20: 1 | L20: Turquía | M20: =(Q20*3)+R20 | N20: =O20-P20 | O20: =Z20+AA20 | P20: =AB20+AC20 | Q20: =T20+U20 | R20: =V20+W20 | S20: =X20+Y20 | T20: =COUNTIFS(C:C,L20,G:G,"Local") | U20: =COUNTIFS(D:D,L20,G:G,"Visitante") | V20: =COUNTIFS(C:C,L20,G:G,"Empate") | W20: =COUNTIFS(D:D,L20,G:G,"Empate") | X20: =COUNTIFS(C:C,L20,G:G,"Visitante") | Y20: =COUNTIFS(D:D,L20,G:G,"Local") | Z20: =SUMIF(C:C,L20,E:E) | AA20: =SUMIF(D:D,L20,F:F) | AB20: =SUMIF(C:C,L20,F:F) | AC20: =SUMIF(D:D,L20,E:E)
A21: 20 | B21: D | C21: Australia | D21: Turquía | E21: 0 | F21: 2 | G21: =IF(E21>F21,"Local",IF(E21=F21,"Empate","Visitante")) | H21: =E21-F21 | K21: 2 | L21: Paraguay | M21: =(Q21*3)+R21 | N21: =O21-P21 | O21: =Z21+AA21 | P21: =AB21+AC21 | Q21: =T21+U21 | R21: =V21+W21 | S21: =X21+Y21 | T21: =COUNTIFS(C:C,L21,G:G,"Local") | U21: =COUNTIFS(D:D,L21,G:G,"Visitante") | V21: =COUNTIFS(C:C,L21,G:G,"Empate") | W21: =COUNTIFS(D:D,L21,G:G,"Empate") | X21: =COUNTIFS(C:C,L21,G:G,"Visitante") | Y21: =COUNTIFS(D:D,L21,G:G,"Local") | Z21: =SUMIF(C:C,L21,E:E) | AA21: =SUMIF(D:D,L21,F:F) | AB21: =SUMIF(C:C,L21,F:F) | AC21: =SUMIF(D:D,L21,E:E)
A22: 21 | B22: D | C22: Estados Unidos | D22: Australia | E22: 2 | F22: 1 | G22: =IF(E22>F22,"Local",IF(E22=F22,"Empate","Visitante")) | H22: =E22-F22 | K22: 3 | L22: Estados Unidos | M22: =(Q22*3)+R22 | N22: =O22-P22 | O22: =Z22+AA22 | P22: =AB22+AC22 | Q22: =T22+U22 | R22: =V22+W22 | S22: =X22+Y22 | T22: =COUNTIFS(C:C,L22,G:G,"Local") | U22: =COUNTIFS(D:D,L22,G:G,"Visitante") | V22: =COUNTIFS(C:C,L22,G:G,"Empate") | W22: =COUNTIFS(D:D,L22,G:G,"Empate") | X22: =COUNTIFS(C:C,L22,G:G,"Visitante") | Y22: =COUNTIFS(D:D,L22,G:G,"Local") | Z22: =SUMIF(C:C,L22,E:E) | AA22: =SUMIF(D:D,L22,F:F) | AB22: =SUMIF(C:C,L22,F:F) | AC22: =SUMIF(D:D,L22,E:E)
A23: 22 | B23: D | C23: Turquía | D23: Paraguay | E23: 1 | F23: 1 | G23: =IF(E23>F23,"Local",IF(E23=F23,"Empate","Visitante")) | H23: =E23-F23 | K23: 4 | L23: Australia | M23: =(Q23*3)+R23 | N23: =O23-P23 | O23: =Z23+AA23 | P23: =AB23+AC23 | Q23: =T23+U23 | R23: =V23+W23 | S23: =X23+Y23 | T23: =COUNTIFS(C:C,L23,G:G,"Local") | U23: =COUNTIFS(D:D,L23,G:G,"Visitante") | V23: =COUNTIFS(C:C,L23,G:G,"Empate") | W23: =COUNTIFS(D:D,L23,G:G,"Empate") | X23: =COUNTIFS(C:C,L23,G:G,"Visitante") | Y23: =COUNTIFS(D:D,L23,G:G,"Local") | Z23: =SUMIF(C:C,L23,E:E) | AA23: =SUMIF(D:D,L23,F:F) | AB23: =SUMIF(C:C,L23,F:F) | AC23: =SUMIF(D:D,L23,E:E)
A24: 23 | B24: D | C24: Turquía | D24: Estados Unidos | E24: 3 | F24: 1 | G24: =IF(E24>F24,"Local",IF(E24=F24,"Empate","Visitante")) | H24: =E24-F24
A25: 24 | B25: D | C25: Paraguay | D25: Australia | E25: 3 | F25: 1 | G25: =IF(E25>F25,"Local",IF(E25=F25,"Empate","Visitante")) | H25: =E25-F25 | J25: Grupo | K25: Posición | L25: Equipo | M25: Puntos | N25: Diferencia | O25: GF | P25: GC | Q25: Victorias | R25: Empates | S25: Derrotas | T25: Victorias_L | U25: Victorias_V | V25: Empates_L | W25: Empates_V | X25: Derrotas_L | Y25: Derrotas_V | Z25: GF_L | AA25: GF_V | AB25: GC_L | AC25: GC_V
A26: 25 | B26: E | C26: Alemania | D26: Curazao | E26: 4 | F26: 0 | G26: =IF(E26>F26,"Local",IF(E26=F26,"Empate","Visitante")) | H26: =E26-F26 | J26: E | K26: 1 | L26: Alemania | M26: =(Q26*3)+R26 | N26: =O26-P26 | O26: =Z26+AA26 | P26: =AB26+AC26 | Q26: =T26+U26 | R26: =V26+W26 | S26: =X26+Y26 | T26: =COUNTIFS(C:C,L26,G:G,"Local") | U26: =COUNTIFS(D:D,L26,G:G,"Visitante") | V26: =COUNTIFS(C:C,L26,G:G,"Empate") | W26: =COUNTIFS(D:D,L26,G:G,"Empate") | X26: =COUNTIFS(C:C,L26,G:G,"Visitante") | Y26: =COUNTIFS(D:D,L26,G:G,"Local") | Z26: =SUMIF(C:C,L26,E:E) | AA26: =SUMIF(D:D,L26,F:F) | AB26: =SUMIF(C:C,L26,F:F) | AC26: =SUMIF(D:D,L26,E:E)
A27: 26 | B27: E | C27: Costa de Marfil | D27: Ecuador | E27: 1 | F27: 1 | G27: =IF(E27>F27,"Local",IF(E27=F27,"Empate","Visitante")) | H27: =E27-F27 | K27: 2 | L27: Ecuador | M27: =(Q27*3)+R27 | N27: =O27-P27 | O27: =Z27+AA27 | P27: =AB27+AC27 | Q27: =T27+U27 | R27: =V27+W27 | S27: =X27+Y27 | T27: =COUNTIFS(C:C,L27,G:G,"Local") | U27: =COUNTIFS(D:D,L27,G:G,"Visitante") | V27: =COUNTIFS(C:C,L27,G:G,"Empate") | W27: =COUNTIFS(D:D,L27,G:G,"Empate") | X27: =COUNTIFS(C:C,L27,G:G,"Visitante") | Y27: =COUNTIFS(D:D,L27,G:G,"Local") | Z27: =SUMIF(C:C,L27,E:E) | AA27: =SUMIF(D:D,L27,F:F) | AB27: =SUMIF(C:C,L27,F:F) | AC27: =SUMIF(D:D,L27,E:E)
A28: 27 | B28: E | C28: Alemania | D28: Costa de Marfil | E28: 3 | F28: 1 | G28: =IF(E28>F28,"Local",IF(E28=F28,"Empate","Visitante")) | H28: =E28-F28 | K28: 3 | L28: Costa de Marfil | M28: =(Q28*3)+R28 | N28: =O28-P28 | O28: =Z28+AA28 | P28: =AB28+AC28 | Q28: =T28+U28 | R28: =V28+W28 | S28: =X28+Y28 | T28: =COUNTIFS(C:C,L28,G:G,"Local") | U28: =COUNTIFS(D:D,L28,G:G,"Visitante") | V28: =COUNTIFS(C:C,L28,G:G,"Empate") | W28: =COUNTIFS(D:D,L28,G:G,"Empate") | X28: =COUNTIFS(C:C,L28,G:G,"Visitante") | Y28: =COUNTIFS(D:D,L28,G:G,"Local") | Z28: =SUMIF(C:C,L28,E:E) | AA28: =SUMIF(D:D,L28,F:F) | AB28: =SUMIF(C:C,L28,F:F) | AC28: =SUMIF(D:D,L28,E:E)
A29: 28 | B29: E | C29: Ecuador | D29: Curazao | E29: 3 | F29: 0 | G29: =IF(E29>F29,"Local",IF(E29=F29,"Empate","Visitante")) | H29: =E29-F29 | K29: 4 | L29: Curazao | M29: =(Q29*3)+R29 | N29: =O29-P29 | O29: =Z29+AA29 | P29: =AB29+AC29 | Q29: =T29+U29 | R29: =V29+W29 | S29: =X29+Y29 | T29: =COUNTIFS(C:C,L29,G:G,"Local") | U29: =COUNTIFS(D:D,L29,G:G,"Visitante") | V29: =COUNTIFS(C:C,L29,G:G,"Empate") | W29: =COUNTIFS(D:D,L29,G:G,"Empate") | X29: =COUNTIFS(C:C,L29,G:G,"Visitante") | Y29: =COUNTIFS(D:D,L29,G:G,"Local") | Z29: =SUMIF(C:C,L29,E:E) | AA29: =SUMIF(D:D,L29,F:F) | AB29: =SUMIF(C:C,L29,F:F) | AC29: =SUMIF(D:D,L29,E:E)
A30: 29 | B30: E | C30: Curazao | D30: Costa de Marfil | E30: 0 | F30: 3 | G30: =IF(E30>F30,"Local",IF(E30=F30,"Empate","Visitante")) | H30: =E30-F30
A31: 30 | B31: E | C31: Ecuador | D31: Alemania | E31: 1 | F31: 2 | G31: =IF(E31>F31,"Local",IF(E31=F31,"Empate","Visitante")) | H31: =E31-F31 | J31: Grupo | K31: Posición | L31: Equipo | M31: Puntos | N31: Diferencia | O31: GF | P31: GC | Q31: Victorias | R31: Empates | S31: Derrotas | T31: Victorias_L | U31: Victorias_V | V31: Empates_L | W31: Empates_V | X31: Derrotas_L | Y31: Derrotas_V | Z31: GF_L | AA31: GF_V | AB31: GC_L | AC31: GC_V
A32: 31 | B32: F | C32: Países Bajos | D32: Japón | E32: 1 | F32: 2 | G32: =IF(E32>F32,"Local",IF(E32=F32,"Empate","Visitante")) | H32: =E32-F32 | J32: F | K32: 1 | L32: Japón | M32: =(Q32*3)+R32 | N32: =O32-P32 | O32: =Z32+AA32 | P32: =AB32+AC32 | Q32: =T32+U32 | R32: =V32+W32 | S32: =X32+Y32 | T32: =COUNTIFS(C:C,L32,G:G,"Local") | U32: =COUNTIFS(D:D,L32,G:G,"Visitante") | V32: =COUNTIFS(C:C,L32,G:G,"Empate") | W32: =COUNTIFS(D:D,L32,G:G,"Empate") | X32: =COUNTIFS(C:C,L32,G:G,"Visitante") | Y32: =COUNTIFS(D:D,L32,G:G,"Local") | Z32: =SUMIF(C:C,L32,E:E) | AA32: =SUMIF(D:D,L32,F:F) | AB32: =SUMIF(C:C,L32,F:F) | AC32: =SUMIF(D:D,L32,E:E)
A33: 32 | B33: F | C33: Suecia | D33: Túnez | E33: 1 | F33: 0 | G33: =IF(E33>F33,"Local",IF(E33=F33,"Empate","Visitante")) | H33: =E33-F33 | K33: 2 | L33: Países Bajos | M33: =(Q33*3)+R33 | N33: =O33-P33 | O33: =Z33+AA33 | P33: =AB33+AC33 | Q33: =T33+U33 | R33: =V33+W33 | S33: =X33+Y33 | T33: =COUNTIFS(C:C,L33,G:G,"Local") | U33: =COUNTIFS(D:D,L33,G:G,"Visitante") | V33: =COUNTIFS(C:C,L33,G:G,"Empate") | W33: =COUNTIFS(D:D,L33,G:G,"Empate") | X33: =COUNTIFS(C:C,L33,G:G,"Visitante") | Y33: =COUNTIFS(D:D,L33,G:G,"Local") | Z33: =SUMIF(C:C,L33,E:E) | AA33: =SUMIF(D:D,L33,F:F) | AB33: =SUMIF(C:C,L33,F:F) | AC33: =SUMIF(D:D,L33,E:E)
A34: 33 | B34: F | C34: Países Bajos | D34: Suecia | E34: 1 | F34: 1 | G34: =IF(E34>F34,"Local",IF(E34=F34,"Empate","Visitante")) | H34: =E34-F34 | K34: 3 | L34: Suecia | M34: =(Q34*3)+R34 | N34: =O34-P34 | O34: =Z34+AA34 | P34: =AB34+AC34 | Q34: =T34+U34 | R34: =V34+W34 | S34: =X34+Y34 | T34: =COUNTIFS(C:C,L34,G:G,"Local") | U34: =COUNTIFS(D:D,L34,G:G,"Visitante") | V34: =COUNTIFS(C:C,L34,G:G,"Empate") | W34: =COUNTIFS(D:D,L34,G:G,"Empate") | X34: =COUNTIFS(C:C,L34,G:G,"Visitante") | Y34: =COUNTIFS(D:D,L34,G:G,"Local") | Z34: =SUMIF(C:C,L34,E:E) | AA34: =SUMIF(D:D,L34,F:F) | AB34: =SUMIF(C:C,L34,F:F) | AC34: =SUMIF(D:D,L34,E:E)
A35: 34 | B35: F | C35: Túnez | D35: Japón | E35: 0 | F35: 2 | G35: =IF(E35>F35,"Local",IF(E35=F35,"Empate","Visitante")) | H35: =E35-F35 | K35: 4 | L35: Túnez | M35: =(Q35*3)+R35 | N35: =O35-P35 | O35: =Z35+AA35 | P35: =AB35+AC35 | Q35: =T35+U35 | R35: =V35+W35 | S35: =X35+Y35 | T35: =COUNTIFS(C:C,L35,G:G,"Local") | U35: =COUNTIFS(D:D,L35,G:G,"Visitante") | V35: =COUNTIFS(C:C,L35,G:G,"Empate") | W35: =COUNTIFS(D:D,L35,G:G,"Empate") | X35: =COUNTIFS(C:C,L35,G:G,"Visitante") | Y35: =COUNTIFS(D:D,L35,G:G,"Local") | Z35: =SUMIF(C:C,L35,E:E) | AA35: =SUMIF(D:D,L35,F:F) | AB35: =SUMIF(C:C,L35,F:F) | AC35: =SUMIF(D:D,L35,E:E)
A36: 35 | B36: F | C36: Japón | D36: Suecia | E36: 2 | F36: 1 | G36: =IF(E36>F36,"Local",IF(E36=F36,"Empate","Visitante")) | H36: =E36-F36
A37: 36 | B37: F | C37: Túnez | D37: Países Bajos | E37: 0 | F37: 2 | G37: =IF(E37>F37,"Local",IF(E37=F37,"Empate","Visitante")) | H37: =E37-F37 | J37: Grupo | K37: Posición | L37: Equipo | M37: Puntos | N37: Diferencia | O37: GF | P37: GC | Q37: Victorias | R37: Empates | S37: Derrotas | T37: Victorias_L | U37: Victorias_V | V37: Empates_L | W37: Empates_V | X37: Derrotas_L | Y37: Derrotas_V | Z37: GF_L | AA37: GF_V | AB37: GC_L | AC37: GC_V
A38: 37 | B38: G | C38: Bélgica | D38: Egipto | E38: 2 | F38: 1 | G38: =IF(E38>F38,"Local",IF(E38=F38,"Empate","Visitante")) | H38: =E38-F38 | J38: G | K38: 1 | L38: Bélgica | M38: =(Q38*3)+R38 | N38: =O38-P38 | O38: =Z38+AA38 | P38: =AB38+AC38 | Q38: =T38+U38 | R38: =V38+W38 | S38: =X38+Y38 | T38: =COUNTIFS(C:C,L38,G:G,"Local") | U38: =COUNTIFS(D:D,L38,G:G,"Visitante") | V38: =COUNTIFS(C:C,L38,G:G,"Empate") | W38: =COUNTIFS(D:D,L38,G:G,"Empate") | X38: =COUNTIFS(C:C,L38,G:G,"Visitante") | Y38: =COUNTIFS(D:D,L38,G:G,"Local") | Z38: =SUMIF(C:C,L38,E:E) | AA38: =SUMIF(D:D,L38,F:F) | AB38: =SUMIF(C:C,L38,F:F) | AC38: =SUMIF(D:D,L38,E:E)
A39: 38 | B39: G | C39: Irán | D39: Nueva Zelanda | E39: 2 | F39: 0 | G39: =IF(E39>F39,"Local",IF(E39=F39,"Empate","Visitante")) | H39: =E39-F39 | K39: 2 | L39: Egipto | M39: =(Q39*3)+R39 | N39: =O39-P39 | O39: =Z39+AA39 | P39: =AB39+AC39 | Q39: =T39+U39 | R39: =V39+W39 | S39: =X39+Y39 | T39: =COUNTIFS(C:C,L39,G:G,"Local") | U39: =COUNTIFS(D:D,L39,G:G,"Visitante") | V39: =COUNTIFS(C:C,L39,G:G,"Empate") | W39: =COUNTIFS(D:D,L39,G:G,"Empate") | X39: =COUNTIFS(C:C,L39,G:G,"Visitante") | Y39: =COUNTIFS(D:D,L39,G:G,"Local") | Z39: =SUMIF(C:C,L39,E:E) | AA39: =SUMIF(D:D,L39,F:F) | AB39: =SUMIF(C:C,L39,F:F) | AC39: =SUMIF(D:D,L39,E:E)
A40: 39 | B40: G | C40: Bélgica | D40: Irán | E40: 2 | F40: 1 | G40: =IF(E40>F40,"Local",IF(E40=F40,"Empate","Visitante")) | H40: =E40-F40 | K40: 3 | L40: Irán | M40: =(Q40*3)+R40 | N40: =O40-P40 | O40: =Z40+AA40 | P40: =AB40+AC40 | Q40: =T40+U40 | R40: =V40+W40 | S40: =X40+Y40 | T40: =COUNTIFS(C:C,L40,G:G,"Local") | U40: =COUNTIFS(D:D,L40,G:G,"Visitante") | V40: =COUNTIFS(C:C,L40,G:G,"Empate") | W40: =COUNTIFS(D:D,L40,G:G,"Empate") | X40: =COUNTIFS(C:C,L40,G:G,"Visitante") | Y40: =COUNTIFS(D:D,L40,G:G,"Local") | Z40: =SUMIF(C:C,L40,E:E) | AA40: =SUMIF(D:D,L40,F:F) | AB40: =SUMIF(C:C,L40,F:F) | AC40: =SUMIF(D:D,L40,E:E)
...

Sheet Bracket_Oscar
A1: Dieciseisavos | D1: Octavos | G1: Cuartos | J1: Semifinal | M1: Tercero puesto | P1: Final | S1: Tercero | T1: Campeón
A2: 74 | B2: 1E | C2: Alemania | D2: 89 | E2: W74 | F2: Alemania | G2: 97 | H2: W89 | I2: Francia | J2: 101 | K2: W97 | L2: Francia | M2: 103 | N2: L101 | O2: Francia | P2: 104 | Q2: W101 | R2: España
B3: 3ABCDF | C3: Escocia | E3: W77 | F3: Francia | H3: W90 | I3: Japón | K3: W98 | L3: España | N3: L102 | O3: Argentina | Q3: W102 | R3: Brasil
A4: 77 | B4: 1I | C4: Francia | D4: 90 | E4: W73 | F4: Canadá | G4: 98 | H4: W93 | I4: España | J4: 102 | K4: W99 | L4: Brasil
B5: 3CDFGH | C5: Suecia | E5: W75 | F5: Japón | H5: W94 | I5: Bélgica | K5: W100 | L5: Argentina
A6: 73 | B6: 2A | C6: República Checa | D6: 93 | E6: W83 | F6: Colombia | G6: 99 | H6: W91 | I6: Brasil
B7: 2B | C7: Canadá | E7: W84 | F7: España | H7: W92 | I7: Inglaterra
A8: 75 | B8: 1F | C8: Japón | D8: 94 | E8: W81 | F8: Turquía | G8: 100 | H8: W95 | I8: Argentina
B9: 2C | C9: Marruecos | E9: W82 | F9: Bélgica | H9: W96 | I9: Portugal
A10: 83 | B10: 2K | C10: Colombia | D10: 91 | E10: W76 | F10: Brasil
B11: 2L | C11: Croacia | E11: W78 | F11: Noruega
A12: 84 | B12: 1H | C12: España | D12: 92 | E12: W79 | F12: México
B13: 2J | C13: Austria | E13: W80 | F13: Inglaterra
A14: 81 | B14: 1D | C14: Turquía | D14: 95 | E14: W86 | F14: Argentina
B15: 3BEFIJ | C15: Argelia | E15: W88 | F15: Paraguay
A16: 82 | B16: 1G | C16: Bélgica | D16: 96 | E16: W85 | F16: Suiza
B17: 3AEHIJ | C17: Corea del Sur | E17: W87 | F17: Portugal
A18: 76 | B18: 1C | C18: Brasil
B19: 2F | C19: Países Bajos
A20: 78 | B20: 2E | C20: Ecuador
B21: 2I | C21: Noruega
A22: 79 | B22: 1A | C22: México
B23: 3CEFHI | C23: Costa de Marfil
A24: 80 | B24: 1L | C24: Inglaterra
B25: 3EHIJK | C25: Senegal
A26: 86 | B26: 1J | C26: Argentina
B27: 2H | C27: Uruguay
A28: 88 | B28: 2D | C28: Paraguay
B29: 2G | C29: Egipto
A30: 85 | B30: 1B | C30: Suiza
B31: 3EFGIJ | C31: Irán
A32: 87 | B32: 1K | C32: Portugal
B33: 3DEIJL | C33: Ghana

Sheet Playoffs_Oscar
A1: Dieciseisavos | B1: Octavos | C1: Cuartos | D1: Semifinal | E1: Tercero | F1: Final | G1: Campeón
A2: Alemania | B2: Alemania | C2: Francia | D2: Francia | E2: Francia | F2: España | G2: España
A3: Escocia | B3: Francia | C3: Japón | D3: España | F3: Brasil
A4: Francia | B4: Canadá | C4: España | D4: Brasil
A5: Suecia | B5: Japón | C5: Bélgica | D5: Argentina
A6: República Checa | B6: Colombia | C6: Brasil
A7: Canadá | B7: España | C7: Inglaterra
A8: Japón | B8: Turquía | C8: Argentina
A9: Marruecos | B9: Bélgica | C9: Portugal
A10: Colombia | B10: Brasil
A11: Croacia | B11: Noruega
A12: España | B12: México
A13: Austria | B13: Inglaterra
A14: Turquía | B14: Argentina
A15: Argelia | B15: Paraguay
A16: Bélgica | B16: Suiza
A17: Corea del Sur | B17: Portugal
A18: Brasil
A19: Países Bajos
A20: Ecuador
A21: Noruega
A22: México
A23: Costa de Marfil
A24: Inglaterra
A25: Senegal
A26: Argentina
A27: Uruguay
A28: Paraguay
A29: Egipto
... A33: Ghana

Sheet Playoffs_Predicciones_Oscar
A1: PARTIDOS DE DIECISEISAVOS
A2: Partido | B2: Local | C2: Visitante | D2: G_Local | E2: G_Visitante | F2: Resultado | G2: Diferencia
A3: 1 | B3: Alemania | C3: Paraguay | D3: 2 | E3: 0 | F3: =IF(D3>E3,"Local",IF(D3=E3,"Empate","Visitante")) | G3: =D3-E3
A4: 2 | B4: Francia | C4: Suecia | D4: 3 | E4: 1 | F4: =IF(D4>E4,"Local",IF(D4=E4,"Empate","Visitante")) | G4: =D4-E4
A5: 3 | B5: Sudáfrica | C5: Canadá | D5: 1 | E5: 2 | F5: =IF(D5>E5,"Local",IF(D5=E5,"Empate","Visitante")) | G5: =D5-E5
A6: 4 | B6: Países Bajos | C6: Marruecos | D6: 2 | E6: 1 | F6: =IF(D6>E6,"Local",IF(D6=E6,"Empate","Visitante")) | G6: =D6-E6
A7: 5 | B7: Portugal | C7: Croacia | D7: 2 | E7: 1 | F7: =IF(D7>E7,"Local",IF(D7=E7,"Empate","Visitante")) | G7: =D7-E7
A8: 6 | B8: España | C8: Austria | D8: 2 | E8: 0 | F8: =IF(D8>E8,"Local",IF(D8=E8,"Empate","Visitante")) | G8: =D8-E8
A9: 7 | B9: Estados Unidos | C9: Bosnia y Herzegovina | D9: 2 | E9: 0 | F9: =IF(D9>E9,"Local",IF(D9=E9,"Empate","Visitante")) | G9: =D9-E9
A10: 8 | B10: Bélgica | C10: Senegal | D10: 1 | E10: 2 | F10: =IF(D10>E10,"Local",IF(D10=E10,"Empate","Visitante")) | G10: =D10-E10
A11: 9 | B11: Brasil | C11: Japón | D11: 3 | E11: 1 | F11: =IF(D11>E11,"Local",IF(D11=E11,"Empate","Visitante")) | G11: =D11-E11
A12: 10 | B12: Costa de Marfil | C12: Noruega | D12: 1 | E12: 2 | F12: =IF(D12>E12,"Local",IF(D12=E12,"Empate","Visitante")) | G12: =D12-E12
A13: 11 | B13: México | C13: Ecuador | D13: 2 | E13: 1 | F13: =IF(D13>E13,"Local",IF(D13=E13,"Empate","Visitante")) | G13: =D13-E13
A14: 12 | B14: Inglaterra | C14: RD Congo | D14: 3 | E14: 1 | F14: =IF(D14>E14,"Local",IF(D14=E14,"Empate","Visitante")) | G14: =D14-E14
... A18: 16 | B18: Colombia | C18: Ghana | D18: 2 | E18: 1 | F18: =IF(D18>E18,"Local",IF(D18=E18,"Empate","Visitante")) | G18: =D18-E18
A20: PARTIDOS DE OCTAVOS DE FINAL
A21: Partido | B21: Local | C21: Visitante | D21: G_Local | E21: G_Visitante | F21: Resultado | G21: Diferencia
A22: 1 | B22: Paraguay | C22: Francia | D22: 0 | E22: 3 | F22: =IF(D22>E22,"Local",IF(D22=E22,"Empate","Visitante")) | G22: =D22-E22
A23: 2 | B23: Canadá | C23: Marruecos | D23: 0 | E23: 2 | F23: =IF(D23>E23,"Local",IF(D23=E23,"Empate","Visitante")) | G23: =D23-E23
A24: 3 | B24: Portugal | C24: España | D24: 1 | E24: 2 | F24: =IF(D24>E24,"Local",IF(D24=E24,"Empate","Visitante")) | G24: =D24-E24
A25: 4 | B25: Estados Unidos | C25: Bélgica | D25: 1 | E25: 2 | F25: =IF(D25>E25,"Local",IF(D25=E25,"Empate","Visitante")) | G25: =D25-E25
A26: 5 | B26: Brasil | C26: Noruega | D26: 3 | E26: 1 | F26: =IF(D26>E26,"Local",IF(D26=E26,"Empate","Visitante")) | G26: =D26-E26
A27: 6 | B27: México | C27: Inglaterra | D27: 1 | E27: 2 | F27: =IF(D27>E27,"Local",IF(D27=E27,"Empate","Visitante")) | G27: =D27-E27
A28: 7 | B28: Argentina | C28: Egipto | D28: 2 | E28: 0 | F28: =IF(D28>E28,"Local",IF(D28=E28,"Empate","Visitante")) | G28: =D28-E28
A29: 8 | B29: Suiza | C29: Colombia | D29: 1 | E29: 2 | F29: =IF(D29>E29,"Local",IF(D29=E29,"Empate","Visitante")) | G29: =D29-E29
A31: PARTIDOS DE CUARTOS DE FINAL
A32: Partido | B32: Local | C32: Visitante | D32: G_Local | E32: G_Visitante | F32: Resultado | G32: Diferencia
A33: 1 | B33: Francia | C33: Marruecos | D33: 2 | E33: 1 | F33: =IF(D33>E33,"Local",IF(D33=E33,"Empate","Visitante")) | G33: =D33-E33
A34: 2 | B34: España | C34: Bélgica | D34: 2 | E34: 0 | F34: =IF(D34>E34,"Local",IF(D34=E34,"Empate","Visitante")) | G34: =D34-E34
A35: 3 | B35: Noruega | C35: {=IF(OR(INDEX($F$23:$F$29,(ROW()-33)*2+2)="Empate",INDEX($F$23:$F$29,(ROW()-33)*2+2)=""),"",IF(INDEX($F$23:$F$29,(ROW()-33)*2+2)="Local",INDEX($B$23:$B$29,(ROW()-33)*2+2),INDEX($C$23:$C$29,(ROW()-33)*2+2)))} | D35: 1 | E35: 2 | F35: =IF(D35>E35,"Local",IF(D35=E35,"Empate","Visitante")) | G35: =D35-E35
A36: 4 | B36: Argentina | C36: Suiza | D36: 2 | E36: 1 | F36: =IF(D36>E36,"Local",IF(D36=E36,"Empate","Visitante")) | G36: =D36-E36
A38: PARTIDOS DE SEMIFINAL
A39: Partido | B39: Local | C39: Visitante | D39: G_Local | E39: G_Visitante | F39: Resultado | G39: Diferencia
A40: 1 | B40: Francia | C40: España | D40: 2 | E40: 3 | F40: =IF(D40>E40,"Local",IF(D40=E40,"Empate","Visitante")) | G40: =D40-E40
A41: 2 | B41: Inglaterra | C41: Argentina | D41: 1 | E41: 1 | F41: =IF(D41>E41,"Local",IF(D41=E41,"Empate","Visitante")) | G41: =D41-E41
A43: PARTIDOS DE TERCEROS
A44: Partido | B44: Local | C44: Visitante | D44: G_Local | E44: G_Visitante | F44: Resultado | G44: Diferencia
A45: 1 | B45: Francia | C45: Inglaterra | D45: 3 | E45: 1 | F45: =IF(D45>E45,"Local",IF(D45=E45,"Empate","Visitante")) | G45: =D45-E45
A47: PARTIDOS DE FINAL
A48: Partido | B48: Local | C48: Visitante | D48: G_Local | E48: G_Visitante | F48: Resultado | G48: Diferencia
...

Sheet Predicciones_Camilo
A1: Partido | B1: Grupo | C1: Local | D1: Visitante | E1: G_Local | F1: G_Visitante | G1: Resultado | H1: Diferencia | J1: Grupo | K1: Posición | L1: Equipo | M1: Puntos | N1: Diferencia | O1: GF | P1: GC | Q1: Victorias | R1: Empates | S1: Derrotas | T1: Victorias_L | U1: Victorias_V | V1: Empates_L | W1: Empates_V | X1: Derrotas_L | Y1: Derrotas_V | Z1: GF_L | AA1: GF_V | AB1: GC_L | AC1: GC_V
A2: 1 | B2: A | C2: México | D2: Sudáfrica | E2: 2 | F2: 0 | G2: =IF(E2>F2,"Local",IF(E2=F2,"Empate","Visitante")) | H2: =E2-F2 | J2: A | K2: 1 | L2: México | M2: =(Q2*3)+R2 | N2: =O2-P2 | O2: =Z2+AA2 | P2: =AB2+AC2 | Q2: =T2+U2 | R2: =V2+W2 | S2: =X2+Y2 | T2: =COUNTIFS(C:C,L2,G:G,"Local") | U2: =COUNTIFS(D:D,L2,G:G,"Visitante") | V2: =COUNTIFS(C:C,L2,G:G,"Empate") | W2: =COUNTIFS(D:D,L2,G:G,"Empate") | X2: =COUNTIFS(C:C,L2,G:G,"Visitante") | Y2: =COUNTIFS(D:D,L2,G:G,"Local") | Z2: =SUMIF(C:C,L2,E:E) | AA2: =SUMIF(D:D,L2,F:F) | AB2: =SUMIF(C:C,L2,F:F) | AC2: =SUMIF(D:D,L2,E:E)
A3: 2 | B3: A | C3: Corea del Sur | D3: República Checa | E3: 1 | F3: 1 | G3: =IF(E3>F3,"Local",IF(E3=F3,"Empate","Visitante")) | H3: =E3-F3 | K3: 2 | L3: Corea del Sur | M3: =(Q3*3)+R3 | N3: =O3-P3 | O3: =Z3+AA3 | P3: =AB3+AC3 | Q3: =T3+U3 | R3: =V3+W3 | S3: =X3+Y3 | T3: =COUNTIFS(C:C,L3,G:G,"Local") | U3: =COUNTIFS(D:D,L3,G:G,"Visitante") | V3: =COUNTIFS(C:C,L3,G:G,"Empate") | W3: =COUNTIFS(D:D,L3,G:G,"Empate") | X3: =COUNTIFS(C:C,L3,G:G,"Visitante") | Y3: =COUNTIFS(D:D,L3,G:G,"Local") | Z3: =SUMIF(C:C,L3,E:E) | AA3: =SUMIF(D:D,L3,F:F) | AB3: =SUMIF(C:C,L3,F:F) | AC3: =SUMIF(D:D,L3,E:E)
A4: 3 | B4: A | C4: República Checa | D4: Sudáfrica | E4: 3 | F4: 1 | G4: =IF(E4>F4,"Local",IF(E4=F4,"Empate","Visitante")) | H4: =E4-F4 | K4: 3 | L4: República Checa | M4: =(Q4*3)+R4 | N4: =O4-P4 | O4: =Z4+AA4 | P4: =AB4+AC4 | Q4: =T4+U4 | R4: =V4+W4 | S4: =X4+Y4 | T4: =COUNTIFS(C:C,L4,G:G,"Local") | U4: =COUNTIFS(D:D,L4,G:G,"Visitante") | V4: =COUNTIFS(C:C,L4,G:G,"Empate") | W4: =COUNTIFS(D:D,L4,G:G,"Empate") | X4: =COUNTIFS(C:C,L4,G:G,"Visitante") | Y4: =COUNTIFS(D:D,L4,G:G,"Local") | Z4: =SUMIF(C:C,L4,E:E) | AA4: =SUMIF(D:D,L4,F:F) | AB4: =SUMIF(C:C,L4,F:F) | AC4: =SUMIF(D:D,L4,E:E)
A5: 4 | B5: A | C5: México | D5: Corea del Sur | E5: 2 | F5: 2 | G5: =IF(E5>F5,"Local",IF(E5=F5,"Empate","Visitante")) | H5: =E5-F5 | K5: 4 | L5: Sudáfrica | M5: =(Q5*3)+R5 | N5: =O5-P5 | O5: =Z5+AA5 | P5: =AB5+AC5 | Q5: =T5+U5 | R5: =V5+W5 | S5: =X5+Y5 | T5: =COUNTIFS(C:C,L5,G:G,"Local") | U5: =COUNTIFS(D:D,L5,G:G,"Visitante") | V5: =COUNTIFS(C:C,L5,G:G,"Empate") | W5: =COUNTIFS(D:D,L5,G:G,"Empate") | X5: =COUNTIFS(C:C,L5,G:G,"Visitante") | Y5: =COUNTIFS(D:D,L5,G:G,"Local") | Z5: =SUMIF(C:C,L5,E:E) | AA5: =SUMIF(D:D,L5,F:F) | AB5: =SUMIF(C:C,L5,F:F) | AC5: =SUMIF(D:D,L5,E:E)
